<?xml version="1.0" ?>
<!-- =================================================================================== -->
<!-- |    This document was autogenerated by xacro from robot.urdf.xacro               | -->
<!-- |    EDITING THIS FILE BY HAND IS NOT RECOMMENDED                                 | -->
<!-- =================================================================================== -->
<robot name="hana">
  <!-- Specify some standard inertial calculations https://en.wikipedia.org/wiki/List_of_moments_of_inertia -->
  <!-- These make use of xacro's mathematical functionality -->
  <material name="white">
    <color rgba="1 1 1 1"/>
  </material>
  <link name="base_footprint"/>
  <joint name="base_link_fixed_joint" type="fixed">
    <parent link="base_footprint"/>
    <child link="base_link"/>
    <origin rpy="0 0 0" xyz="0 0 0.03"/>
  </joint>
  <link name="base_link"/>
  <joint name="chassis_fixed_joint" type="fixed">
    <parent link="base_link"/>
    <child link="chassis"/>
    <origin rpy="0 0 0" xyz="0 0 0"/>
  </joint>
  <link name="chassis">
    <visual>
      <origin rpy="0 0 0" xyz="0 0 0"/>
      <geometry>
        <mesh filename="package://hana_description/meshes/visual/base_link.dae" scale="1 1 1"/>
      </geometry>
    </visual>
    <collision>
      <origin rpy="0 0 0" xyz="-0.01 0 0.01"/>
      <geometry>
        <box size="0.1 0.08 0.06"/>
      </geometry>
    </collision>
    <inertial>
      <origin rpy="0 0 0" xyz="-0.01 0 0.01"/>
      <mass value="1.0"/>
      <inertia ixx="0.0008333333333333333" ixy="0.0" ixz="0.0" iyy="0.0011333333333333334" iyz="0.0" izz="0.0013666666666666666"/>
    </inertial>
  </link>
  <joint name="caster_fixed_joint" type="fixed">
    <parent link="chassis"/>
    <child link="caster"/>
    <origin rpy="0 0 0" xyz="-0.044 0 -0.02"/>
  </joint>
  <link name="caster">
    <visual>
      <origin rpy="0 0 0" xyz="0 0 0"/>
      <geometry>
        <sphere radius="0.01"/>
      </geometry>
      <material name="white"/>
    </visual>
    <collision>
      <origin rpy="0 0 0" xyz="0 0 0"/>
      <geometry>
        <sphere radius="0.01"/>
      </geometry>
    </collision>
    <inertial>
      <origin rpy="0 0 0" xyz="0 0 0"/>
      <mass value="0.7"/>
      <inertia ixx="2.8e-05" ixy="0.0" ixz="0.0" iyy="2.8e-05" iyz="0.0" izz="2.8e-05"/>
    </inertial>
  </link>
  <joint name="left_wheel_joint" type="continuous">
    <parent link="base_link"/>
    <child link="left_wheel"/>
    <origin rpy="-1.5707963267948966 0 0" xyz="0 0.055 0"/>
    <axis xyz="0 0 1"/>
  </joint>
  <link name="left_wheel">
    <visual>
      <origin rpy="0 0 0" xyz="0 0 0"/>
      <geometry>
        <mesh filename="package://hana_description/meshes/visual/wheel.dae" scale="1 1 1"/>
      </geometry>
    </visual>
    <collision>
      <origin rpy="0 0 0" xyz="0 0 0"/>
      <geometry>
        <cylinder length="0.014" radius="0.03"/>
      </geometry>
    </collision>
    <inertial>
      <origin rpy="0 0 0" xyz="0 0 0"/>
      <mass value="0.05"/>
      <inertia ixx="1.2066666666666666e-05" ixy="0.0" ixz="0.0" iyy="1.2066666666666666e-05" iyz="0.0" izz="2.25e-05"/>
    </inertial>
  </link>
  <joint name="right_wheel_joint" type="continuous">
    <parent link="base_link"/>
    <child link="right_wheel"/>
    <origin rpy="1.5707963267948966 0 0" xyz="0 -0.055 0"/>
    <axis xyz="0 0 -1"/>
  </joint>
  <link name="right_wheel">
    <visual>
      <origin rpy="0 0 0" xyz="0 0 0"/>
      <geometry>
        <mesh filename="package://hana_description/meshes/visual/wheel.dae" scale="1 1 1"/>
      </geometry>
    </visual>
    <collision>
      <origin rpy="0 0 0" xyz="0 0 0"/>
      <geometry>
        <cylinder length="0.014" radius="0.03"/>
      </geometry>
    </collision>
    <inertial>
      <origin rpy="0 0 0" xyz="0 0 0"/>
      <mass value="0.05"/>
      <inertia ixx="1.2066666666666666e-05" ixy="0.0" ixz="0.0" iyy="1.2066666666666666e-05" iyz="0.0" izz="2.25e-05"/>
    </inertial>
  </link>
  <link name="ul_sensor_mount">
    <visual>
      <origin rpy="0 0 0" xyz="0 0 0"/>
      <geometry>
        <mesh filename="package://hana_description/meshes/visual/ul_sensor.dae" scale="1 1 1"/>
      </geometry>
    </visual>
    <collision>
      <origin rpy="0 0 0" xyz="0 0 0"/>
      <geometry>
        <mesh filename="package://hana_description/meshes/collision/ul_sensor.stl" scale="1 1 1"/>
      </geometry>
    </collision>
    <inertial>
      <origin rpy="0 0 0" xyz="0.005 0 0.013"/>
      <mass value="0.050000"/>
      <inertia ixx="0.000005" ixy="0" ixz="-0.000001" iyy="0.000004" iyz="0" izz="0.000003"/>
    </inertial>
  </link>
  <joint name="ul_sensor_mount_fixed_joint" type="fixed">
    <parent link="chassis"/>
    <child link="ul_sensor_mount"/>
    <origin rpy="0 0 0" xyz="0.038 -0.002 -0.0035"/>
  </joint>
  <link name="ul_sensor_link"/>
  <joint name="ul_sensor_link_fixed_joint" type="fixed">
    <parent link="ul_sensor_mount"/>
    <child link="ul_sensor_link"/>
    <origin rpy="0 0 0" xyz="0.01 0 0"/>
  </joint>
  <link name="front_camera_mount">
    <visual>
      <origin rpy="0 0 0" xyz="0 0 0"/>
      <geometry>
        <mesh filename="package://hana_description/meshes/visual/camera.dae" scale="1 1 1"/>
      </geometry>
    </visual>
    <collision>
      <origin rpy="0 0 0" xyz="0 0 0"/>
      <geometry>
        <mesh filename="package://hana_description/meshes/collision/camera.stl" scale="1 1 1"/>
      </geometry>
    </collision>
    <inertial>
      <origin rpy="0 0 0" xyz="0.005 0 0.013"/>
      <mass value="0.050000"/>
      <inertia ixx="0.000005" ixy="0" ixz="-0.000001" iyy="0.000004" iyz="0" izz="0.000003"/>
    </inertial>
  </link>
  <joint name="front_camera_mount_fixed_joint" type="fixed">
    <parent link="chassis"/>
    <child link="front_camera_mount"/>
    <origin rpy="0 0 0" xyz="0.05 -0.001 0.028"/>
  </joint>
  <link name="camera_link"/>
  <joint name="camera_link_fixed_joint" type="fixed">
    <parent link="front_camera_mount"/>
    <child link="camera_link"/>
    <origin rpy="-1.5707963267948966 0 -1.5707963267948966" xyz="0.001 0 0.003"/>
  </joint>
  <link name="lidar_lidar_mount">
    <visual>
      <origin rpy="0 0 0" xyz="0 0 0"/>
      <geometry>
        <mesh filename="package://hana_description/meshes/visual/lidar.dae" scale="1 1 1"/>
      </geometry>
    </visual>
    <collision>
      <origin rpy="0 0 0" xyz="0 0 0"/>
      <geometry>
        <mesh filename="package://hana_description/meshes/collision/lidar.stl" scale="1 1 1"/>
      </geometry>
    </collision>
    <inertial>
      <origin rpy="0 0 0" xyz="0.007 0 0.025"/>
      <mass value="0.110"/>
      <inertia ixx="0.000058" ixy="0" ixz="0.000005" iyy="0.000099" iyz="0" izz="0.000103"/>
    </inertial>
  </link>
  <joint name="lidar_mount_fixed_joint" type="fixed">
    <parent link="chassis"/>
    <child link="lidar_lidar_mount"/>
    <origin rpy="0 0 0" xyz="0 0 0.042"/>
  </joint>
  <link name="laser_link"/>
  <joint name="laser_link_fixed_joint" type="fixed">
    <parent link="lidar_lidar_mount"/>
    <child link="laser_link"/>
    <origin rpy="0 0 3.141592653589793" xyz="0.0 0 0.03"/>
  </joint>
  <link name="imu_link"/>
  <joint name="imu_link_joint" type="fixed">
    <parent link="chassis"/>
    <child link="imu_link"/>
    <origin rpy="0 0 0" xyz="0 0 0.03"/>
  </joint>
  <gazebo reference="laser_link">
    <sensor name="laser" type="gpu_lidar">
      <always_on>true</always_on>
      <visualize>true</visualize>
      <pose> 0 0 0 0 0 0 </pose>
      <update_rate>5</update_rate>
      <topic>scan</topic>
      <gz_frame_id>laser_link</gz_frame_id>
      <lidar>
        <scan>
          <horizontal>
            <samples>360</samples>
            <resolution>1</resolution>
            <min_angle>-3.141592653589793</min_angle>
            <max_angle>3.141592653589793</max_angle>
          </horizontal>
        </scan>
        <range>
          <min>0.12</min>
          <max>8.0</max>
          <resolution>0.05</resolution>
        </range>
        <noise>
          <type>gaussian</type>
          <mean>0.0</mean>
          <stddev>0.01</stddev>
        </noise>
      </lidar>
    </sensor>
  </gazebo>
  <gazebo reference="camera_link">
    <sensor name="camera" type="camera">
      <pose>0 0 0 0 -1.5708 1.5708</pose>
      <always_on>true</always_on>
      <visualize>true</visualize>
      <update_rate>30</update_rate>
      <topic>camera/image_raw</topic>
      <gz_frame_id>camera_rgb_frame</gz_frame_id>
      <camera name="hana_camera">
        <camera_info_topic>camera/camera_info</camera_info_topic>
        <horizontal_fov>1.08</horizontal_fov>
        <image>
          <width>1280</width>
          <height>720</height>
          <format>R8G8B8</format>
        </image>
        <clip>
          <near>0.02</near>
          <far>300</far>
        </clip>
        <noise>
          <type>gaussian</type>
          <mean>0.0</mean>
          <stddev>0.01</stddev>
        </noise>
      </camera>
    </sensor>
  </gazebo>
  <gazebo reference="imu_link">
    <sensor name="tb3_imu" type="imu">
      <always_on>true</always_on>
      <update_rate>200</update_rate>
      <topic>imu</topic>
      <!-- 250627 KSH -->
      <gz_frame_id>imu_link</gz_frame_id>
      <imu>
        <angular_velocity>
          <x>
            <noise type="gaussian">
              <mean>0.0</mean>
              <stddev>2e-4</stddev>
            </noise>
          </x>
          <y>
            <noise type="gaussian">
              <mean>0.0</mean>
              <stddev>2e-4</stddev>
            </noise>
          </y>
          <z>
            <noise type="gaussian">
              <mean>0.0</mean>
              <stddev>2e-4</stddev>
            </noise>
          </z>
        </angular_velocity>
        <linear_acceleration>
          <x>
            <noise type="gaussian">
              <mean>0.0</mean>
              <stddev>1.7e-2</stddev>
            </noise>
          </x>
          <y>
            <noise type="gaussian">
              <mean>0.0</mean>
              <stddev>1.7e-2</stddev>
            </noise>
          </y>
          <z>
            <noise type="gaussian">
              <mean>0.0</mean>
              <stddev>1.7e-2</stddev>
            </noise>
          </z>
        </linear_acceleration>
      </imu>
    </sensor>
  </gazebo>
  <gazebo reference="left_wheel">
    <mu1 value="1.2"/>
    <mu2 value="1.2"/>
  </gazebo>
  <gazebo reference="right_wheel">
    <mu1 value="1.2"/>
    <mu2 value="1.2"/>
  </gazebo>
  <gazebo reference="base_link">
    <mu1 value="0.01"/>
    <mu2 value="0.01"/>
  </gazebo>
  <gazebo reference="caster">
    <mu1 value="0.01"/>
    <mu2 value="0.01"/>
  </gazebo>
  <gazebo>
    <plugin filename="gz-sim-diff-drive-system" name="gz::sim::systems::DiffDrive">
      <left_joint>left_wheel_joint</left_joint>
      <right_joint>right_wheel_joint</right_joint>
      <wheel_separation>0.096</wheel_separation>
      <wheel_radius>0.03</wheel_radius>
      <min_velocity>-0.5</min_velocity>
      <max_velocity>0.5</max_velocity>
      <min_acceleration>-2.0</min_acceleration>
      <max_acceleration>2.0</max_acceleration>
      <topic>cmd_vel</topic>
      <!--250629 KSH-->
      <!-- <odom_topic>odom</odom_topic>
            <frame_id>odom</frame_id>
            <child_frame_id>base_footprint</child_frame_id>
            <odom_publisher_frequency>30</odom_publisher_frequency> -->
      <!-- <tf_topic>/tf</tf_topic> -->
    </plugin>
    <plugin filename="gz-sim-joint-state-publisher-system" name="gz::sim::systems::JointStatePublisher">
      <topic>joint_states</topic>
      <joint_name>left_wheel_joint</joint_name>
      <joint_name>right_wheel_joint</joint_name>
    </plugin>
  </gazebo>
</robot>
